Workbook

Sheet Painel
A1: ANÁLISE COMERCIAL
A2: VENDAS • PRODUTOS • CLIENTES • LOJAS • RENTABILIDADE
A4: FATURAMENTO BRUTO | C4: PEDIDOS ENTREGUES | E4: TICKET MÉDIO | G4: LUCRO APÓS DESCONTOS | I4: MARGEM DE LUCRO | K4: DESCONTOS CONCEDIDOS
A5: =SUM(Resumo_Mensal!C5:C28) | C5: =SUM(Resumo_Mensal!H5:H28) | E5: =IFERROR(SUM(Resumo_Mensal!E5:E28)/SUM(Resumo_Mensal!H5:H28),0) | G5: =SUM(Resumo_Mensal!F5:F28) | I5: =IFERROR(SUM(Resumo_Mensal!F5:F28)/SUM(Resumo_Mensal!E5:E28),0) | K5: =SUM(Resumo_Mensal!D5:D28)
H23: COMO USAR
H24: As abas de análise usam fórmulas para responder às 10 perguntas de negócio. Filtre as tabelas, ordene por receita/lucro e confira as conclusões. Ao abrir no Excel, aguarde o recálculo das fórmulas.

Sheet Leia-me
A1: Campo | B1: Descrição
A2: Objetivo | B2: Projeto de portfólio de análise comercial e rentabilidade com SQL Server, Excel e Power BI.
A3: Natureza dos dados | B3: Todos os registros são fictícios e foram gerados para fins educacionais; não representam uma empresa real.
A4: Período | B4: Pedidos entre 01/01/2024 e 31/12/2025.
A5: Tabelas | B5: Clientes, Produtos, Lojas, Pedidos, ItensPedido, MetasMensais e DicionarioDados.
A6: Relacionamentos principais | B6: Pedidos.ClienteID -> Clientes.ClienteID; Pedidos.LojaID -> Lojas.LojaID; ItensPedido.PedidoID -> Pedidos.PedidoID; ItensPedido.ProdutoID -> Produtos.ProdutoID; MetasMensais.LojaID -> Lojas.LojaID.
A7: Observação importante | B7: As metas são referências fictícias. Para análises financeiras, defina claramente se cancelados/devolvidos serão excluídos e como tratar descontos.
A8: Sugestão de uso | B8: Comece por auditoria e qualidade dos dados; depois faça consultas SQL, valide indicadores no Excel e crie o modelo e dashboard no Power BI.

Sheet Clientes
A1: ClienteID | B1: NomeCliente | C1: Segmento | D1: Cidade | E1: Regiao | F1: DataCadastro
A2: C0001 | B2: Daniel Silva | C2: Pequena Empresa | D2: Salvador | E2: Nordeste | F2: 45063
A3: C0002 | B3: Eduarda Souza | C3: Pequena Empresa | D3: Campinas | E3: Sudeste | F3: 45678
A4: C0003 | B4: Vitória Gomes | C4: Pessoa Física | D4: Rio de Janeiro | E4: Sudeste | F4: 44753
A5: C0004 | B5: Henrique Barbosa | C5: Pequena Empresa | D5: Campinas | E5: Sudeste | F5: 45711
A6: C0005 | B6: Beatriz Dias | C6: Pessoa Física | D6: Campinas | E6: Sudeste | F6: 45481
A7: C0006 | B7: Isabela Silva | C7: Pequena Empresa | D7: Campo Grande | E7: Centro-Oeste | F7: 44888
A8: C0007 | B8: Otávio Araújo | C8: Pessoa Física | D8: Recife | E8: Nordeste | F8: 45002
A9: C0008 | B9: Larissa Souza | C9: Pessoa Física | D9: Fortaleza | E9: Nordeste | F9: 44760
A10: C0009 | B10: André Fernandes | C10: Pequena Empresa | D10: Porto Alegre | E10: Sul | F10: 44650
A11: C0010 | B11: Paula Dias | C11: Pessoa Física | D11: Recife | E11: Nordeste | F11: 45337
A12: C0011 | B12: Thiago Lima | C12: Média Empresa | D12: Rio de Janeiro | E12: Sudeste | F12: 45828
A13: C0012 | B13: Vitória Rodrigues | C13: Pequena Empresa | D13: Porto Alegre | E13: Sul | F13: 44655
... A351: C0350 | B351: Natália Barbosa | C351: Pessoa Física | D351: Fortaleza | E351: Nordeste | F351: 44893

Sheet Produtos
A1: ProdutoID | B1: NomeProduto | C1: Categoria | D1: CustoUnitario | E1: PrecoUnitario | F1: Fornecedor
A2: P001 | B2: Luminária Essencial 01 | C2: Móveis | D2: 1093.14 | E2: 1929.3 | F2: Fornecedor 16
A3: P002 | B3: Pasta Compacto 02 | C3: Papelaria | D3: 1682.52 | E3: 2787.33 | F3: Fornecedor 04
A4: P003 | B4: Caderno Compacto 03 | C4: Papelaria | D4: 1376.45 | E4: 1875.79 | F4: Fornecedor 05
A5: P004 | B5: Smartphone Premium 04 | C5: Telefonia | D5: 1704.19 | E5: 2264.47 | F5: Fornecedor 12
A6: P005 | B6: Memória RAM Plus 05 | C6: Informática | D6: 107.22 | E6: 162.58 | F6: Fornecedor 13
A7: P006 | B7: SSD Essencial 06 | C7: Informática | D7: 413.48 | E7: 576.19 | F7: Fornecedor 11
A8: P007 | B8: Mesa Premium 07 | C8: Móveis | D8: 80.49 | E8: 144.45 | F8: Fornecedor 05
A9: P008 | B9: Cabo USB Essencial 08 | C9: Telefonia | D9: 1112.24 | E9: 1987.49 | F9: Fornecedor 09
A10: P009 | B10: Luminária Compacto 09 | C10: Móveis | D10: 279.34 | E10: 505.59 | F10: Fornecedor 17
A11: P010 | B11: Smartphone Essencial 10 | C11: Telefonia | D11: 1399.8 | E11: 1874.64 | F11: Fornecedor 02
A12: P011 | B12: Armário Essencial 11 | C12: Móveis | D12: 1154.45 | E12: 1843.98 | F12: Fornecedor 04
A13: P012 | B13: Tablet Compacto 12 | C13: Telefonia | D13: 970.46 | E13: 1556.05 | F13: Fornecedor 08
... A71: P070 | B71: Agenda Pro 70 | C71: Papelaria | D71: 1776.38 | E71: 2760.05 | F71: Fornecedor 05

Sheet Lojas
A1: LojaID | B1: NomeLoja | C1: Cidade | D1: Regiao | E1: MetaMensal
A2: L01 | B2: Loja Paulista | C2: São Paulo | D2: Sudeste | E2: 145000
A3: L02 | B3: Loja Campinas | C3: Campinas | D3: Sudeste | E3: 85000
A4: L03 | B4: Loja Carioca | C4: Rio de Janeiro | D4: Sudeste | E4: 110000
A5: L04 | B5: Loja Minas | C5: Belo Horizonte | D5: Sudeste | E5: 90000
A6: L05 | B6: Loja Curitiba | C6: Curitiba | D6: Sul | E6: 78000
A7: L06 | B7: Loja Gaúcha | C7: Porto Alegre | D7: Sul | E7: 72000
A8: L07 | B8: Loja Capital | C8: Brasília | D8: Centro-Oeste | E8: 80000
A9: L08 | B9: Loja Recife | C9: Recife | D9: Nordeste | E9: 65000

Sheet Pedidos
A1: PedidoID | B1: DataPedido | C1: ClienteID | D1: LojaID | E1: StatusPedido | F1: FormaPagamento | G1: DescontoPedidoPct
A2: PED00001 | B2: 45495 | C2: C0309 | D2: L07 | E2: Entregue | F2: Pix | G2: 0
A3: PED00002 | B3: 45919 | C3: C0164 | D3: L03 | E3: Entregue | F3: Cartão de crédito | G3: 0.1
A4: PED00003 | B4: 45718 | C4: C0299 | D4: L05 | E4: Entregue | F4: Cartão de débito | G4: 0.05
A5: PED00004 | B5: 45884 | C5: C0296 | D5: L04 | E5: Entregue | F5: Cartão de crédito | G5: 0
A6: PED00005 | B6: 45999 | C6: C0105 | D6: L07 | E6: Entregue | F6: Cartão de crédito | G6: 0.03
A7: PED00006 | B7: 45984 | C7: C0349 | D7: L05 | E7: Entregue | F7: Pix | G7: 0
A8: PED00007 | B8: 45572 | C8: C0148 | D8: L02 | E8: Entregue | F8: Cartão de crédito | G8: 0.1
A9: PED00008 | B9: 45744 | C9: C0336 | D9: L05 | E9: Entregue | F9: Pix | G9: 0.1
A10: PED00009 | B10: 45835 | C10: C0116 | D10: L04 | E10: Entregue | F10: Cartão de crédito | G10: 0.05
A11: PED00010 | B11: 45453 | C11: C0209 | D11: L08 | E11: Entregue | F11: Pix | G11: 0.15
A12: PED00011 | B12: 45330 | C12: C0090 | D12: L07 | E12: Cancelado | F12: Pix | G12: 0.1
A13: PED00012 | B13: 45771 | C13: C0140 | D13: L04 | E13: Entregue | F13: Cartão de crédito | G13: 0.05
... A1801: PED01800 | B1801: 45420 | C1801: C0188 | D1801: L05 | E1801: Entregue | F1801: Boleto | G1801: 0

Sheet ItensPedido
A1: ItemPedidoID | B1: PedidoID | C1: ProdutoID | D1: Quantidade | E1: DescontoItemPct
A2: IT00001_01 | B2: PED00001 | C2: P061 | D2: 2 | E2: 0
A3: IT00001_02 | B3: PED00001 | C3: P067 | D3: 2 | E3: 0
A4: IT00002_01 | B4: PED00002 | C4: P065 | D4: 2 | E4: 0
A5: IT00002_02 | B5: PED00002 | C5: P066 | D5: 2 | E5: 0
A6: IT00002_03 | B6: PED00002 | C6: P069 | D6: 1 | E6: 0
A7: IT00003_01 | B7: PED00003 | C7: P061 | D7: 1 | E7: 0.02
A8: IT00004_01 | B8: PED00004 | C8: P049 | D8: 1 | E8: 0.05
A9: IT00004_02 | B9: PED00004 | C9: P019 | D9: 1 | E9: 0
A10: IT00004_03 | B10: PED00004 | C10: P032 | D10: 1 | E10: 0
A11: IT00005_01 | B11: PED00005 | C11: P008 | D11: 2 | E11: 0.1
A12: IT00005_02 | B12: PED00005 | C12: P018 | D12: 2 | E12: 0
A13: IT00005_03 | B13: PED00005 | C13: P067 | D13: 5 | E13: 0
... A4546: IT01800_03 | B4546: PED01800 | C4546: P011 | D4546: 4 | E4546: 0.02

Sheet MetasMensais
A1: LojaID | B1: MesReferencia | C1: MetaFaturamento
A2: L01 | B2: 45292 | C2: 135231.04
A3: L01 | B3: 45323 | C3: 138211.09
A4: L01 | B4: 45352 | C4: 160620.71
A5: L01 | B5: 45383 | C5: 134125.4
A6: L01 | B6: 45413 | C6: 145177.66
A7: L01 | B7: 45444 | C7: 156644.99
A8: L01 | B8: 45474 | C8: 143132.46
A9: L01 | B9: 45505 | C9: 159575.02
A10: L01 | B10: 45536 | C10: 138750.13
A11: L01 | B11: 45566 | C11: 161124.05
A12: L01 | B12: 45597 | C12: 140971.46
A13: L01 | B13: 45627 | C13: 148733.33
... A193: L08 | B193: 45992 | C193: 70978.3

Sheet DicionarioDados
A1: Tabela | B1: Coluna | C1: Descricao
A2: Clientes | B2: ClienteID | C2: Identificador único do cliente (chave primária).
A3: Clientes | B3: NomeCliente | C3: Nome fictício do cliente.
A4: Clientes | B4: Segmento | C4: Perfil do cliente.
A5: Clientes | B5: Cidade | C5: Cidade do cliente.
A6: Clientes | B6: Regiao | C6: Região do cliente.
A7: Clientes | B7: DataCadastro | C7: Data de cadastro do cliente.
A8: Produtos | B8: ProdutoID | C8: Identificador único do produto (chave primária).
A9: Produtos | B9: NomeProduto | C9: Nome fictício do produto.
A10: Produtos | B10: Categoria | C10: Categoria comercial do produto.
A11: Produtos | B11: CustoUnitario | C11: Custo fictício por unidade.
A12: Produtos | B12: PrecoUnitario | C12: Preço de venda de referência por unidade.
... A33: MetasMensais | B33: MetaFaturamento | C33: Meta de faturamento mensal fictícia.

Sheet Base_Analise
A1: ItemPedidoID | B1: PedidoID | C1: ProdutoID | D1: Quantidade | E1: DescontoItemPct | F1: DataPedido | G1: Ano | H1: Mês Nº | I1: StatusPedido | J1: ClienteID | K1: LojaID | L1: FormaPagamento | M1: DescontoPedidoPct | N1: NomeProduto | O1: Categoria | P1: CustoUnitario | Q1: PrecoUnitario | R1: FaturamentoBruto | S1: DescontoItemR$ | T1: DescontoPedidoR$ | U1: ReceitaLiquida | V1: CustoTotal | W1: LucroLiquido | X1: MargemLucroPct
A2: =ItensPedido!A2 | B2: =ItensPedido!B2 | C2: =ItensPedido!C2 | D2: =ItensPedido!D2 | E2: =ItensPedido!E2 | F2: =IFERROR(INDEX(Pedidos!$B$2:$B$1801,MATCH(B2,Pedidos!$A$2:$A$1801,0)),0) | G2: =IF(F2=0,"",YEAR(F2)) | H2: =IF(F2=0,"",MONTH(F2)) | I2: =IFERROR(INDEX(Pedidos!$E$2:$E$1801,MATCH(B2,Pedidos!$A$2:$A$1801,0)),"") | J2: =IFERROR(INDEX(Pedidos!$C$2:$C$1801,MATCH(B2,Pedidos!$A$2:$A$1801,0)),"") | K2: =IFERROR(INDEX(Pedidos!$D$2:$D$1801,MATCH(B2,Pedidos!$A$2:$A$1801,0)),"") | L2: =IFERROR(INDEX(Pedidos!$F$2:$F$1801,MATCH(B2,Pedidos!$A$2:$A$1801,0)),"") | M2: =IFERROR(INDEX(Pedidos!$G$2:$G$1801,MATCH(B2,Pedidos!$A$2:$A$1801,0)),0) | N2: =IFERROR(INDEX(Produtos!$B$2:$B$71,MATCH(C2,Produtos!$A$2:$A$71,0)),"") | O2: =IFERROR(INDEX(Produtos!$C$2:$C$71,MATCH(C2,Produtos!$A$2:$A$71,0)),"") | P2: =IFERROR(INDEX(Produtos!$D$2:$D$71,MATCH(C2,Produtos!$A$2:$A$71,0)),0) | Q2: =IFERROR(INDEX(Produtos!$E$2:$E$71,MATCH(C2,Produtos!$A$2:$A$71,0)),0) | R2: =D2*Q2 | S2: =R2*E2 | T2: =(R2-S2)*M2 | U2: =R2-S2-T2 | V2: =D2*P2 | W2: =U2-V2 | X2: =IFERROR(W2/U2,0)
A3: =ItensPedido!A3 | B3: =ItensPedido!B3 | C3: =ItensPedido!C3 | D3: =ItensPedido!D3 | E3: =ItensPedido!E3 | F3: =IFERROR(INDEX(Pedidos!$B$2:$B$1801,MATCH(B3,Pedidos!$A$2:$A$1801,0)),0) | G3: =IF(F3=0,"",YEAR(F3)) | H3: =IF(F3=0,"",MONTH(F3)) | I3: =IFERROR(INDEX(Pedidos!$E$2:$E$1801,MATCH(B3,Pedidos!$A$2:$A$1801,0)),"") | J3: =IFERROR(INDEX(Pedidos!$C$2:$C$1801,MATCH(B3,Pedidos!$A$2:$A$1801,0)),"") | K3: =IFERROR(INDEX(Pedidos!$D$2:$D$1801,MATCH(B3,Pedidos!$A$2:$A$1801,0)),"") | L3: =IFERROR(INDEX(Pedidos!$F$2:$F$1801,MATCH(B3,Pedidos!$A$2:$A$1801,0)),"") | M3: =IFERROR(INDEX(Pedidos!$G$2:$G$1801,MATCH(B3,Pedidos!$A$2:$A$1801,0)),0) | N3: =IFERROR(INDEX(Produtos!$B$2:$B$71,MATCH(C3,Produtos!$A$2:$A$71,0)),"") | O3: =IFERROR(INDEX(Produtos!$C$2:$C$71,MATCH(C3,Produtos!$A$2:$A$71,0)),"") | P3: =IFERROR(INDEX(Produtos!$D$2:$D$71,MATCH(C3,Produtos!$A$2:$A$71,0)),0) | Q3: =IFERROR(INDEX(Produtos!$E$2:$E$71,MATCH(C3,Produtos!$A$2:$A$71,0)),0) | R3: =D3*Q3 | S3: =R3*E3 | T3: =(R3-S3)*M3 | U3: =R3-S3-T3 | V3: =D3*P3 | W3: =U3-V3 | X3: =IFERROR(W3/U3,0)
A4: =ItensPedido!A4 | B4: =ItensPedido!B4 | C4: =ItensPedido!C4 | D4: =ItensPedido!D4 | E4: =ItensPedido!E4 | F4: =IFERROR(INDEX(Pedidos!$B$2:$B$1801,MATCH(B4,Pedidos!$A$2:$A$1801,0)),0) | G4: =IF(F4=0,"",YEAR(F4)) | H4: =IF(F4=0,"",MONTH(F4)) | I4: =IFERROR(INDEX(Pedidos!$E$2:$E$1801,MATCH(B4,Pedidos!$A$2:$A$1801,0)),"") | J4: =IFERROR(INDEX(Pedidos!$C$2:$C$1801,MATCH(B4,Pedidos!$A$2:$A$1801,0)),"") | K4: =IFERROR(INDEX(Pedidos!$D$2:$D$1801,MATCH(B4,Pedidos!$A$2:$A$1801,0)),"") | L4: =IFERROR(INDEX(Pedidos!$F$2:$F$1801,MATCH(B4,Pedidos!$A$2:$A$1801,0)),"") | M4: =IFERROR(INDEX(Pedidos!$G$2:$G$1801,MATCH(B4,Pedidos!$A$2:$A$1801,0)),0) | N4: =IFERROR(INDEX(Produtos!$B$2:$B$71,MATCH(C4,Produtos!$A$2:$A$71,0)),"") | O4: =IFERROR(INDEX(Produtos!$C$2:$C$71,MATCH(C4,Produtos!$A$2:$A$71,0)),"") | P4: =IFERROR(INDEX(Produtos!$D$2:$D$71,MATCH(C4,Produtos!$A$2:$A$71,0)),0) | Q4: =IFERROR(INDEX(Produtos!$E$2:$E$71,MATCH(C4,Produtos!$A$2:$A$71,0)),0) | R4: =D4*Q4 | S4: =R4*E4 | T4: =(R4-S4)*M4 | U4: =R4-S4-T4 | V4: =D4*P4 | W4: =U4-V4 | X4: =IFERROR(W4/U4,0)
A5: =ItensPedido!A5 | B5: =ItensPedido!B5 | C5: =ItensPedido!C5 | D5: =ItensPedido!D5 | E5: =ItensPedido!E5 | F5: =IFERROR(INDEX(Pedidos!$B$2:$B$1801,MATCH(B5,Pedidos!$A$2:$A$1801,0)),0) | G5: =IF(F5=0,"",YEAR(F5)) | H5: =IF(F5=0,"",MONTH(F5)) | I5: =IFERROR(INDEX(Pedidos!$E$2:$E$1801,MATCH(B5,Pedidos!$A$2:$A$1801,0)),"") | J5: =IFERROR(INDEX(Pedidos!$C$2:$C$1801,MATCH(B5,Pedidos!$A$2:$A$1801,0)),"") | K5: =IFERROR(INDEX(Pedidos!$D$2:$D$1801,MATCH(B5,Pedidos!$A$2:$A$1801,0)),"") | L5: =IFERROR(INDEX(Pedidos!$F$2:$F$1801,MATCH(B5,Pedidos!$A$2:$A$1801,0)),"") | M5: =IFERROR(INDEX(Pedidos!$G$2:$G$1801,MATCH(B5,Pedidos!$A$2:$A$1801,0)),0) | N5: =IFERROR(INDEX(Produtos!$B$2:$B$71,MATCH(C5,Produtos!$A$2:$A$71,0)),"") | O5: =IFERROR(INDEX(Produtos!$C$2:$C$71,MATCH(C5,Produtos!$A$2:$A$71,0)),"") | P5: =IFERROR(INDEX(Produtos!$D$2:$D$71,MATCH(C5,Produtos!$A$2:$A$71,0)),0) | Q5: =IFERROR(INDEX(Produtos!$E$2:$E$71,MATCH(C5,Produtos!$A$2:$A$71,0)),0) | R5: =D5*Q5 | S5: =R5*E5 | T5: =(R5-S5)*M5 | U5: =R5-S5-T5 | V5: =D5*P5 | W5: =U5-V5 | X5: =IFERROR(W5/U5,0)
A6: =ItensPedido!A6 | B6: =ItensPedido!B6 | C6: =ItensPedido!C6 | D6: =ItensPedido!D6 | E6: =ItensPedido!E6 | F6: =IFERROR(INDEX(Pedidos!$B$2:$B$1801,MATCH(B6,Pedidos!$A$2:$A$1801,0)),0) | G6: =IF(F6=0,"",YEAR(F6)) | H6: =IF(F6=0,"",MONTH(F6)) | I6: =IFERROR(INDEX(Pedidos!$E$2:$E$1801,MATCH(B6,Pedidos!$A$2:$A$1801,0)),"") | J6: =IFERROR(INDEX(Pedidos!$C$2:$C$1801,MATCH(B6,Pedidos!$A$2:$A$1801,0)),"") | K6: =IFERROR(INDEX(Pedidos!$D$2:$D$1801,MATCH(B6,Pedidos!$A$2:$A$1801,0)),"") | L6: =IFERROR(INDEX(Pedidos!$F$2:$F$1801,MATCH(B6,Pedidos!$A$2:$A$1801,0)),"") | M6: =IFERROR(INDEX(Pedidos!$G$2:$G$1801,MATCH(B6,Pedidos!$A$2:$A$1801,0)),0) | N6: =IFERROR(INDEX(Produtos!$B$2:$B$71,MATCH(C6,Produtos!$A$2:$A$71,0)),"") | O6: =IFERROR(INDEX(Produtos!$C$2:$C$71,MATCH(C6,Produtos!$A$2:$A$71,0)),"") | P6: =IFERROR(INDEX(Produtos!$D$2:$D$71,MATCH(C6,Produtos!$A$2:$A$71,0)),0) | Q6: =IFERROR(INDEX(Produtos!$E$2:$E$71,MATCH(C6,Produtos!$A$2:$A$71,0)),0) | R6: =D6*Q6 | S6: =R6*E6 | T6: =(R6-S6)*M6 | U6: =R6-S6-T6 | V6: =D6*P6 | W6: =U6-V6 | X6: =IFERROR(W6/U6,0)
A7: =ItensPedido!A7 | B7: =ItensPedido!B7 | C7: =ItensPedido!C7 | D7: =ItensPedido!D7 | E7: =ItensPedido!E7 | F7: =IFERROR(INDEX(Pedidos!$B$2:$B$1801,MATCH(B7,Pedidos!$A$2:$A$1801,0)),0) | G7: =IF(F7=0,"",YEAR(F7)) | H7: =IF(F7=0,"",MONTH(F7)) | I7: =IFERROR(INDEX(Pedidos!$E$2:$E$1801,MATCH(B7,Pedidos!$A$2:$A$1801,0)),"") | J7: =IFERROR(INDEX(Pedidos!$C$2:$C$1801,MATCH(B7,Pedidos!$A$2:$A$1801,0)),"") | K7: =IFERROR(INDEX(Pedidos!$D$2:$D$1801,MATCH(B7,Pedidos!$A$2:$A$1801,0)),"") | L7: =IFERROR(INDEX(Pedidos!$F$2:$F$1801,MATCH(B7,Pedidos!$A$2:$A$1801,0)),"") | M7: =IFERROR(INDEX(Pedidos!$G$2:$G$1801,MATCH(B7,Pedidos!$A$2:$A$1801,0)),0) | N7: =IFERROR(INDEX(Produtos!$B$2:$B$71,MATCH(C7,Produtos!$A$2:$A$71,0)),"") | O7: =IFERROR(INDEX(Produtos!$C$2:$C$71,MATCH(C7,Produtos!$A$2:$A$71,0)),"") | P7: =IFERROR(INDEX(Produtos!$D$2:$D$71,MATCH(C7,Produtos!$A$2:$A$71,0)),0) | Q7: =IFERROR(INDEX(Produtos!$E$2:$E$71,MATCH(C7,Produtos!$A$2:$A$71,0)),0) | R7: =D7*Q7 | S7: =R7*E7 | T7: =(R7-S7)*M7 | U7: =R7-S7-T7 | V7: =D7*P7 | W7: =U7-V7 | X7: =IFERROR(W7/U7,0)
A8: =ItensPedido!A8 | B8: =ItensPedido!B8 | C8: =ItensPedido!C8 | D8: =ItensPedido!D8 | E8: =ItensPedido!E8 | F8: =IFERROR(INDEX(Pedidos!$B$2:$B$1801,MATCH(B8,Pedidos!$A$2:$A$1801,0)),0) | G8: =IF(F8=0,"",YEAR(F8)) | H8: =IF(F8=0,"",MONTH(F8)) | I8: =IFERROR(INDEX(Pedidos!$E$2:$E$1801,MATCH(B8,Pedidos!$A$2:$A$1801,0)),"") | J8: =IFERROR(INDEX(Pedidos!$C$2:$C$1801,MATCH(B8,Pedidos!$A$2:$A$1801,0)),"") | K8: =IFERROR(INDEX(Pedidos!$D$2:$D$1801,MATCH(B8,Pedidos!$A$2:$A$1801,0)),"") | L8: =IFERROR(INDEX(Pedidos!$F$2:$F$1801,MATCH(B8,Pedidos!$A$2:$A$1801,0)),"") | M8: =IFERROR(INDEX(Pedidos!$G$2:$G$1801,MATCH(B8,Pedidos!$A$2:$A$1801,0)),0) | N8: =IFERROR(INDEX(Produtos!$B$2:$B$71,MATCH(C8,Produtos!$A$2:$A$71,0)),"") | O8: =IFERROR(INDEX(Produtos!$C$2:$C$71,MATCH(C8,Produtos!$A$2:$A$71,0)),"") | P8: =IFERROR(INDEX(Produtos!$D$2:$D$71,MATCH(C8,Produtos!$A$2:$A$71,0)),0) | Q8: =IFERROR(INDEX(Produtos!$E$2:$E$71,MATCH(C8,Produtos!$A$2:$A$71,0)),0) | R8: =D8*Q8 | S8: =R8*E8 | T8: =(R8-S8)*M8 | U8: =R8-S8-T8 | V8: =D8*P8 | W8: =U8-V8 | X8: =IFERROR(W8/U8,0)
A9: =ItensPedido!A9 | B9: =ItensPedido!B9 | C9: =ItensPedido!C9 | D9: =ItensPedido!D9 | E9: =ItensPedido!E9 | F9: =IFERROR(INDEX(Pedidos!$B$2:$B$1801,MATCH(B9,Pedidos!$A$2:$A$1801,0)),0) | G9: =IF(F9=0,"",YEAR(F9)) | H9: =IF(F9=0,"",MONTH(F9)) | I9: =IFERROR(INDEX(Pedidos!$E$2:$E$1801,MATCH(B9,Pedidos!$A$2:$A$1801,0)),"") | J9: =IFERROR(INDEX(Pedidos!$C$2:$C$1801,MATCH(B9,Pedidos!$A$2:$A$1801,0)),"") | K9: =IFERROR(INDEX(Pedidos!$D$2:$D$1801,MATCH(B9,Pedidos!$A$2:$A$1801,0)),"") | L9: =IFERROR(INDEX(Pedidos!$F$2:$F$1801,MATCH(B9,Pedidos!$A$2:$A$1801,0)),"") | M9: =IFERROR(INDEX(Pedidos!$G$2:$G$1801,MATCH(B9,Pedidos!$A$2:$A$1801,0)),0) | N9: =IFERROR(INDEX(Produtos!$B$2:$B$71,MATCH(C9,Produtos!$A$2:$A$71,0)),"") | O9: =IFERROR(INDEX(Produtos!$C$2:$C$71,MATCH(C9,Produtos!$A$2:$A$71,0)),"") | P9: =IFERROR(INDEX(Produtos!$D$2:$D$71,MATCH(C9,Produtos!$A$2:$A$71,0)),0) | Q9: =IFERROR(INDEX(Produtos!$E$2:$E$71,MATCH(C9,Produtos!$A$2:$A$71,0)),0) | R9: =D9*Q9 | S9: =R9*E9 | T9: =(R9-S9)*M9 | U9: =R9-S9-T9 | V9: =D9*P9 | W9: =U9-V9 | X9: =IFERROR(W9/U9,0)
A10: =ItensPedido!A10 | B10: =ItensPedido!B10 | C10: =ItensPedido!C10 | D10: =ItensPedido!D10 | E10: =ItensPedido!E10 | F10: =IFERROR(INDEX(Pedidos!$B$2:$B$1801,MATCH(B10,Pedidos!$A$2:$A$1801,0)),0) | G10: =IF(F10=0,"",YEAR(F10)) | H10: =IF(F10=0,"",MONTH(F10)) | I10: =IFERROR(INDEX(Pedidos!$E$2:$E$1801,MATCH(B10,Pedidos!$A$2:$A$1801,0)),"") | J10: =IFERROR(INDEX(Pedidos!$C$2:$C$1801,MATCH(B10,Pedidos!$A$2:$A$1801,0)),"") | K10: =IFERROR(INDEX(Pedidos!$D$2:$D$1801,MATCH(B10,Pedidos!$A$2:$A$1801,0)),"") | L10: =IFERROR(INDEX(Pedidos!$F$2:$F$1801,MATCH(B10,Pedidos!$A$2:$A$1801,0)),"") | M10: =IFERROR(INDEX(Pedidos!$G$2:$G$1801,MATCH(B10,Pedidos!$A$2:$A$1801,0)),0) | N10: =IFERROR(INDEX(Produtos!$B$2:$B$71,MATCH(C10,Produtos!$A$2:$A$71,0)),"") | O10: =IFERROR(INDEX(Produtos!$C$2:$C$71,MATCH(C10,Produtos!$A$2:$A$71,0)),"") | P10: =IFERROR(INDEX(Produtos!$D$2:$D$71,MATCH(C10,Produtos!$A$2:$A$71,0)),0) | Q10: =IFERROR(INDEX(Produtos!$E$2:$E$71,MATCH(C10,Produtos!$A$2:$A$71,0)),0) | R10: =D10*Q10 | S10: =R10*E10 | T10: =(R10-S10)*M10 | U10: =R10-S10-T10 | V10: =D10*P10 | W10: =U10-V10 | X10: =IFERROR(W10/U10,0)
A11: =ItensPedido!A11 | B11: =ItensPedido!B11 | C11: =ItensPedido!C11 | D11: =ItensPedido!D11 | E11: =ItensPedido!E11 | F11: =IFERROR(INDEX(Pedidos!$B$2:$B$1801,MATCH(B11,Pedidos!$A$2:$A$1801,0)),0) | G11: =IF(F11=0,"",YEAR(F11)) | H11: =IF(F11=0,"",MONTH(F11)) | I11: =IFERROR(INDEX(Pedidos!$E$2:$E$1801,MATCH(B11,Pedidos!$A$2:$A$1801,0)),"") | J11: =IFERROR(INDEX(Pedidos!$C$2:$C$1801,MATCH(B11,Pedidos!$A$2:$A$1801,0)),"") | K11: =IFERROR(INDEX(Pedidos!$D$2:$D$1801,MATCH(B11,Pedidos!$A$2:$A$1801,0)),"") | L11: =IFERROR(INDEX(Pedidos!$F$2:$F$1801,MATCH(B11,Pedidos!$A$2:$A$1801,0)),"") | M11: =IFERROR(INDEX(Pedidos!$G$2:$G$1801,MATCH(B11,Pedidos!$A$2:$A$1801,0)),0) | N11: =IFERROR(INDEX(Produtos!$B$2:$B$71,MATCH(C11,Produtos!$A$2:$A$71,0)),"") | O11: =IFERROR(INDEX(Produtos!$C$2:$C$71,MATCH(C11,Produtos!$A$2:$A$71,0)),"") | P11: =IFERROR(INDEX(Produtos!$D$2:$D$71,MATCH(C11,Produtos!$A$2:$A$71,0)),0) | Q11: =IFERROR(INDEX(Produtos!$E$2:$E$71,MATCH(C11,Produtos!$A$2:$A$71,0)),0) | R11: =D11*Q11 | S11: =R11*E11 | T11: =(R11-S11)*M11 | U11: =R11-S11-T11 | V11: =D11*P11 | W11: =U11-V11 | X11: =IFERROR(W11/U11,0)
A12: =ItensPedido!A12 | B12: =ItensPedido!B12 | C12: =ItensPedido!C12 | D12: =ItensPedido!D12 | E12: =ItensPedido!E12 | F12: =IFERROR(INDEX(Pedidos!$B$2:$B$1801,MATCH(B12,Pedidos!$A$2:$A$1801,0)),0) | G12: =IF(F12=0,"",YEAR(F12)) | H12: =IF(F12=0,"",MONTH(F12)) | I12: =IFERROR(INDEX(Pedidos!$E$2:$E$1801,MATCH(B12,Pedidos!$A$2:$A$1801,0)),"") | J12: =IFERROR(INDEX(Pedidos!$C$2:$C$1801,MATCH(B12,Pedidos!$A$2:$A$1801,0)),"") | K12: =IFERROR(INDEX(Pedidos!$D$2:$D$1801,MATCH(B12,Pedidos!$A$2:$A$1801,0)),"") | L12: =IFERROR(INDEX(Pedidos!$F$2:$F$1801,MATCH(B12,Pedidos!$A$2:$A$1801,0)),"") | M12: =IFERROR(INDEX(Pedidos!$G$2:$G$1801,MATCH(B12,Pedidos!$A$2:$A$1801,0)),0) | N12: =IFERROR(INDEX(Produtos!$B$2:$B$71,MATCH(C12,Produtos!$A$2:$A$71,0)),"") | O12: =IFERROR(INDEX(Produtos!$C$2:$C$71,MATCH(C12,Produtos!$A$2:$A$71,0)),"") | P12: =IFERROR(INDEX(Produtos!$D$2:$D$71,MATCH(C12,Produtos!$A$2:$A$71,0)),0) | Q12: =IFERROR(INDEX(Produtos!$E$2:$E$71,MATCH(C12,Produtos!$A$2:$A$71,0)),0) | R12: =D12*Q12 | S12: =R12*E12 | T12: =(R12-S12)*M12 | U12: =R12-S12-T12 | V12: =D12*P12 | W12: =U12-V12 | X12: =IFERROR(W12/U12,0)
A13: =ItensPedido!A13 | B13: =ItensPedido!B13 | C13: =ItensPedido!C13 | D13: =ItensPedido!D13 | E13: =ItensPedido!E13 | F13: =IFERROR(INDEX(Pedidos!$B$2:$B$1801,MATCH(B13,Pedidos!$A$2:$A$1801,0)),0) | G13: =IF(F13=0,"",YEAR(F13)) | H13: =IF(F13=0,"",MONTH(F13)) | I13: =IFERROR(INDEX(Pedidos!$E$2:$E$1801,MATCH(B13,Pedidos!$A$2:$A$1801,0)),"") | J13: =IFERROR(INDEX(Pedidos!$C$2:$C$1801,MATCH(B13,Pedidos!$A$2:$A$1801,0)),"") | K13: =IFERROR(INDEX(Pedidos!$D$2:$D$1801,MATCH(B13,Pedidos!$A$2:$A$1801,0)),"") | L13: =IFERROR(INDEX(Pedidos!$F$2:$F$1801,MATCH(B13,Pedidos!$A$2:$A$1801,0)),"") | M13: =IFERROR(INDEX(Pedidos!$G$2:$G$1801,MATCH(B13,Pedidos!$A$2:$A$1801,0)),0) | N13: =IFERROR(INDEX(Produtos!$B$2:$B$71,MATCH(C13,Produtos!$A$2:$A$71,0)),"") | O13: =IFERROR(INDEX(Produtos!$C$2:$C$71,MATCH(C13,Produtos!$A$2:$A$71,0)),"") | P13: =IFERROR(INDEX(Produtos!$D$2:$D$71,MATCH(C13,Produtos!$A$2:$A$71,0)),0) | Q13: =IFERROR(INDEX(Produtos!$E$2:$E$71,MATCH(C13,Produtos!$A$2:$A$71,0)),0) | R13: =D13*Q13 | S13: =R13*E13 | T13: =(R13-S13)*M13 | U13: =R13-S13-T13 | V13: =D13*P13 | W13: =U13-V13 | X13: =IFERROR(W13/U13,0)
... A4546: =ItensPedido!A4546 | B4546: =ItensPedido!B4546 | C4546: =ItensPedido!C4546 | D4546: =ItensPedido!D4546 | E4546: =ItensPedido!E4546 | F4546: =IFERROR(INDEX(Pedidos!$B$2:$B$1801,MATCH(B4546,Pedidos!$A$2:$A$1801,0)),0) | G4546: =IF(F4546=0,"",YEAR(F4546)) | H4546: =IF(F4546=0,"",MONTH(F4546)) | I4546: =IFERROR(INDEX(Pedidos!$E$2:$E$1801,MATCH(B4546,Pedidos!$A$2:$A$1801,0)),"") | J4546: =IFERROR(INDEX(Pedidos!$C$2:$C$1801,MATCH(B4546,Pedidos!$A$2:$A$1801,0)),"") | K4546: =IFERROR(INDEX(Pedidos!$D$2:$D$1801,MATCH(B4546,Pedidos!$A$2:$A$1801,0)),"") | L4546: =IFERROR(INDEX(Pedidos!$F$2:$F$1801,MATCH(B4546,Pedidos!$A$2:$A$1801,0)),"") | M4546: =IFERROR(INDEX(Pedidos!$G$2:$G$1801,MATCH(B4546,Pedidos!$A$2:$A$1801,0)),0) | N4546: =IFERROR(INDEX(Produtos!$B$2:$B$71,MATCH(C4546,Produtos!$A$2:$A$71,0)),"") | O4546: =IFERROR(INDEX(Produtos!$C$2:$C$71,MATCH(C4546,Produtos!$A$2:$A$71,0)),"") | P4546: =IFERROR(INDEX(Produtos!$D$2:$D$71,MATCH(C4546,Produtos!$A$2:$A$71,0)),0) | Q4546: =IFERROR(INDEX(Produtos!$E$2:$E$71,MATCH(C4546,Produtos!$A$2:$A$71,0)),0) | R4546: =D4546*Q4546 | S4546: =R4546*E4546 | T4546: =(R4546-S4546)*M4546 | U4546: =R4546-S4546-T4546 | V4546: =D4546*P4546 | W4546: =U4546-V4546 | X4546: =IFERROR(W4546/U4546,0)

Sheet Resumo_Mensal
A1: EVOLUÇÃO MENSAL
A2: Faturamento bruto, descontos, receita líquida, lucro e ticket médio por mês.
A4: Ano | B4: Mês Nº | C4: Faturamento Bruto | D4: Descontos Totais | E4: Receita Líquida | F4: Lucro Após Descontos | G4: Margem Líquida | H4: Pedidos Entregues | I4: Data Mês
A5: 2024 | B5: 1 | C5: =SUMIFS(Base_Analise!$R$2:$R$4546,Base_Analise!$G$2:$G$4546,A5,Base_Analise!$H$2:$H$4546,B5,Base_Analise!$I$2:$I$4546,"Entregue") | D5: =SUMIFS(Base_Analise!$S$2:$S$4546,Base_Analise!$G$2:$G$4546,A5,Base_Analise!$H$2:$H$4546,B5,Base_Analise!$I$2:$I$4546,"Entregue")+SUMIFS(Base_Analise!$T$2:$T$4546,Base_Analise!$G$2:$G$4546,A5,Base_Analise!$H$2:$H$4546,B5,Base_Analise!$I$2:$I$4546,"Entregue") | E5: =SUMIFS(Base_Analise!$U$2:$U$4546,Base_Analise!$G$2:$G$4546,A5,Base_Analise!$H$2:$H$4546,B5,Base_Analise!$I$2:$I$4546,"Entregue") | F5: =SUMIFS(Base_Analise!$W$2:$W$4546,Base_Analise!$G$2:$G$4546,A5,Base_Analise!$H$2:$H$4546,B5,Base_Analise!$I$2:$I$4546,"Entregue") | G5: =IFERROR(F5/C5,0) | H5: =COUNTIFS(Pedidos!$E$2:$E$1801,"Entregue",Pedidos!$B$2:$B$1801,">="&DATE(A5,B5,1),Pedidos!$B$2:$B$1801,"<"&EDATE(DATE(A5,B5,1),1)) | I5: =DATE(A5,B5,1)
A6: 2024 | B6: 2 | C6: =SUMIFS(Base_Analise!$R$2:$R$4546,Base_Analise!$G$2:$G$4546,A6,Base_Analise!$H$2:$H$4546,B6,Base_Analise!$I$2:$I$4546,"Entregue") | D6: =SUMIFS(Base_Analise!$S$2:$S$4546,Base_Analise!$G$2:$G$4546,A6,Base_Analise!$H$2:$H$4546,B6,Base_Analise!$I$2:$I$4546,"Entregue")+SUMIFS(Base_Analise!$T$2:$T$4546,Base_Analise!$G$2:$G$4546,A6,Base_Analise!$H$2:$H$4546,B6,Base_Analise!$I$2:$I$4546,"Entregue") | E6: =SUMIFS(Base_Analise!$U$2:$U$4546,Base_Analise!$G$2:$G$4546,A6,Base_Analise!$H$2:$H$4546,B6,Base_Analise!$I$2:$I$4546,"Entregue") | F6: =SUMIFS(Base_Analise!$W$2:$W$4546,Base_Analise!$G$2:$G$4546,A6,Base_Analise!$H$2:$H$4546,B6,Base_Analise!$I$2:$I$4546,"Entregue") | G6: =IFERROR(F6/C6,0) | H6: =COUNTIFS(Pedidos!$E$2:$E$1801,"Entregue",Pedidos!$B$2:$B$1801,">="&DATE(A6,B6,1),Pedidos!$B$2:$B$1801,"<"&EDATE(DATE(A6,B6,1),1)) | I6: =DATE(A6,B6,1)
A7: 2024 | B7: 3 | C7: =SUMIFS(Base_Analise!$R$2:$R$4546,Base_Analise!$G$2:$G$4546,A7,Base_Analise!$H$2:$H$4546,B7,Base_Analise!$I$2:$I$4546,"Entregue") | D7: =SUMIFS(Base_Analise!$S$2:$S$4546,Base_Analise!$G$2:$G$4546,A7,Base_Analise!$H$2:$H$4546,B7,Base_Analise!$I$2:$I$4546,"Entregue")+SUMIFS(Base_Analise!$T$2:$T$4546,Base_Analise!$G$2:$G$4546,A7,Base_Analise!$H$2:$H$4546,B7,Base_Analise!$I$2:$I$4546,"Entregue") | E7: =SUMIFS(Base_Analise!$U$2:$U$4546,Base_Analise!$G$2:$G$4546,A7,Base_Analise!$H$2:$H$4546,B7,Base_Analise!$I$2:$I$4546,"Entregue") | F7: =SUMIFS(Base_Analise!$W$2:$W$4546,Base_Analise!$G$2:$G$4546,A7,Base_Analise!$H$2:$H$4546,B7,Base_Analise!$I$2:$I$4546,"Entregue") | G7: =IFERROR(F7/C7,0) | H7: =COUNTIFS(Pedidos!$E$2:$E$1801,"Entregue",Pedidos!$B$2:$B$1801,">="&DATE(A7,B7,1),Pedidos!$B$2:$B$1801,"<"&EDATE(DATE(A7,B7,1),1)) | I7: =DATE(A7,B7,1)
A8: 2024 | B8: 4 | C8: =SUMIFS(Base_Analise!$R$2:$R$4546,Base_Analise!$G$2:$G$4546,A8,Base_Analise!$H$2:$H$4546,B8,Base_Analise!$I$2:$I$4546,"Entregue") | D8: =SUMIFS(Base_Analise!$S$2:$S$4546,Base_Analise!$G$2:$G$4546,A8,Base_Analise!$H$2:$H$4546,B8,Base_Analise!$I$2:$I$4546,"Entregue")+SUMIFS(Base_Analise!$T$2:$T$4546,Base_Analise!$G$2:$G$4546,A8,Base_Analise!$H$2:$H$4546,B8,Base_Analise!$I$2:$I$4546,"Entregue") | E8: =SUMIFS(Base_Analise!$U$2:$U$4546,Base_Analise!$G$2:$G$4546,A8,Base_Analise!$H$2:$H$4546,B8,Base_Analise!$I$2:$I$4546,"Entregue") | F8: =SUMIFS(Base_Analise!$W$2:$W$4546,Base_Analise!$G$2:$G$4546,A8,Base_Analise!$H$2:$H$4546,B8,Base_Analise!$I$2:$I$4546,"Entregue") | G8: =IFERROR(F8/C8,0) | H8: =COUNTIFS(Pedidos!$E$2:$E$1801,"Entregue",Pedidos!$B$2:$B$1801,">="&DATE(A8,B8,1),Pedidos!$B$2:$B$1801,"<"&EDATE(DATE(A8,B8,1),1)) | I8: =DATE(A8,B8,1)
A9: 2024 | B9: 5 | C9: =SUMIFS(Base_Analise!$R$2:$R$4546,Base_Analise!$G$2:$G$4546,A9,Base_Analise!$H$2:$H$4546,B9,Base_Analise!$I$2:$I$4546,"Entregue") | D9: =SUMIFS(Base_Analise!$S$2:$S$4546,Base_Analise!$G$2:$G$4546,A9,Base_Analise!$H$2:$H$4546,B9,Base_Analise!$I$2:$I$4546,"Entregue")+SUMIFS(Base_Analise!$T$2:$T$4546,Base_Analise!$G$2:$G$4546,A9,Base_Analise!$H$2:$H$4546,B9,Base_Analise!$I$2:$I$4546,"Entregue") | E9: =SUMIFS(Base_Analise!$U$2:$U$4546,Base_Analise!$G$2:$G$4546,A9,Base_Analise!$H$2:$H$4546,B9,Base_Analise!$I$2:$I$4546,"Entregue") | F9: =SUMIFS(Base_Analise!$W$2:$W$4546,Base_Analise!$G$2:$G$4546,A9,Base_Analise!$H$2:$H$4546,B9,Base_Analise!$I$2:$I$4546,"Entregue") | G9: =IFERROR(F9/C9,0) | H9: =COUNTIFS(Pedidos!$E$2:$E$1801,"Entregue",Pedidos!$B$2:$B$1801,">="&DATE(A9,B9,1),Pedidos!$B$2:$B$1801,"<"&EDATE(DATE(A9,B9,1),1)) | I9: =DATE(A9,B9,1)
A10: 2024 | B10: 6 | C10: =SUMIFS(Base_Analise!$R$2:$R$4546,Base_Analise!$G$2:$G$4546,A10,Base_Analise!$H$2:$H$4546,B10,Base_Analise!$I$2:$I$4546,"Entregue") | D10: =SUMIFS(Base_Analise!$S$2:$S$4546,Base_Analise!$G$2:$G$4546,A10,Base_Analise!$H$2:$H$4546,B10,Base_Analise!$I$2:$I$4546,"Entregue")+SUMIFS(Base_Analise!$T$2:$T$4546,Base_Analise!$G$2:$G$4546,A10,Base_Analise!$H$2:$H$4546,B10,Base_Analise!$I$2:$I$4546,"Entregue") | E10: =SUMIFS(Base_Analise!$U$2:$U$4546,Base_Analise!$G$2:$G$4546,A10,Base_Analise!$H$2:$H$4546,B10,Base_Analise!$I$2:$I$4546,"Entregue") | F10: =SUMIFS(Base_Analise!$W$2:$W$4546,Base_Analise!$G$2:$G$4546,A10,Base_Analise!$H$2:$H$4546,B10,Base_Analise!$I$2:$I$4546,"Entregue") | G10: =IFERROR(F10/C10,0) | H10: =COUNTIFS(Pedidos!$E$2:$E$1801,"Entregue",Pedidos!$B$2:$B$1801,">="&DATE(A10,B10,1),Pedidos!$B$2:$B$1801,"<"&EDATE(DATE(A10,B10,1),1)) | I10: =DATE(A10,B10,1)
A11: 2024 | B11: 7 | C11: =SUMIFS(Base_Analise!$R$2:$R$4546,Base_Analise!$G$2:$G$4546,A11,Base_Analise!$H$2:$H$4546,B11,Base_Analise!$I$2:$I$4546,"Entregue") | D11: =SUMIFS(Base_Analise!$S$2:$S$4546,Base_Analise!$G$2:$G$4546,A11,Base_Analise!$H$2:$H$4546,B11,Base_Analise!$I$2:$I$4546,"Entregue")+SUMIFS(Base_Analise!$T$2:$T$4546,Base_Analise!$G$2:$G$4546,A11,Base_Analise!$H$2:$H$4546,B11,Base_Analise!$I$2:$I$4546,"Entregue") | E11: =SUMIFS(Base_Analise!$U$2:$U$4546,Base_Analise!$G$2:$G$4546,A11,Base_Analise!$H$2:$H$4546,B11,Base_Analise!$I$2:$I$4546,"Entregue") | F11: =SUMIFS(Base_Analise!$W$2:$W$4546,Base_Analise!$G$2:$G$4546,A11,Base_Analise!$H$2:$H$4546,B11,Base_Analise!$I$2:$I$4546,"Entregue") | G11: =IFERROR(F11/C11,0) | H11: =COUNTIFS(Pedidos!$E$2:$E$1801,"Entregue",Pedidos!$B$2:$B$1801,">="&DATE(A11,B11,1),Pedidos!$B$2:$B$1801,"<"&EDATE(DATE(A11,B11,1),1)) | I11: =DATE(A11,B11,1)
A12: 2024 | B12: 8 | C12: =SUMIFS(Base_Analise!$R$2:$R$4546,Base_Analise!$G$2:$G$4546,A12,Base_Analise!$H$2:$H$4546,B12,Base_Analise!$I$2:$I$4546,"Entregue") | D12: =SUMIFS(Base_Analise!$S$2:$S$4546,Base_Analise!$G$2:$G$4546,A12,Base_Analise!$H$2:$H$4546,B12,Base_Analise!$I$2:$I$4546,"Entregue")+SUMIFS(Base_Analise!$T$2:$T$4546,Base_Analise!$G$2:$G$4546,A12,Base_Analise!$H$2:$H$4546,B12,Base_Analise!$I$2:$I$4546,"Entregue") | E12: =SUMIFS(Base_Analise!$U$2:$U$4546,Base_Analise!$G$2:$G$4546,A12,Base_Analise!$H$2:$H$4546,B12,Base_Analise!$I$2:$I$4546,"Entregue") | F12: =SUMIFS(Base_Analise!$W$2:$W$4546,Base_Analise!$G$2:$G$4546,A12,Base_Analise!$H$2:$H$4546,B12,Base_Analise!$I$2:$I$4546,"Entregue") | G12: =IFERROR(F12/C12,0) | H12: =COUNTIFS(Pedidos!$E$2:$E$1801,"Entregue",Pedidos!$B$2:$B$1801,">="&DATE(A12,B12,1),Pedidos!$B$2:$B$1801,"<"&EDATE(DATE(A12,B12,1),1)) | I12: =DATE(A12,B12,1)
A13: 2024 | B13: 9 | C13: =SUMIFS(Base_Analise!$R$2:$R$4546,Base_Analise!$G$2:$G$4546,A13,Base_Analise!$H$2:$H$4546,B13,Base_Analise!$I$2:$I$4546,"Entregue") | D13: =SUMIFS(Base_Analise!$S$2:$S$4546,Base_Analise!$G$2:$G$4546,A13,Base_Analise!$H$2:$H$4546,B13,Base_Analise!$I$2:$I$4546,"Entregue")+SUMIFS(Base_Analise!$T$2:$T$4546,Base_Analise!$G$2:$G$4546,A13,Base_Analise!$H$2:$H$4546,B13,Base_Analise!$I$2:$I$4546,"Entregue") | E13: =SUMIFS(Base_Analise!$U$2:$U$4546,Base_Analise!$G$2:$G$4546,A13,Base_Analise!$H$2:$H$4546,B13,Base_Analise!$I$2:$I$4546,"Entregue") | F13: =SUMIFS(Base_Analise!$W$2:$W$4546,Base_Analise!$G$2:$G$4546,A13,Base_Analise!$H$2:$H$4546,B13,Base_Analise!$I$2:$I$4546,"Entregue") | G13: =IFERROR(F13/C13,0) | H13: =COUNTIFS(Pedidos!$E$2:$E$1801,"Entregue",Pedidos!$B$2:$B$1801,">="&DATE(A13,B13,1),Pedidos!$B$2:$B$1801,"<"&EDATE(DATE(A13,B13,1),1)) | I13: =DATE(A13,B13,1)
A14: 2024 | B14: 10 | C14: =SUMIFS(Base_Analise!$R$2:$R$4546,Base_Analise!$G$2:$G$4546,A14,Base_Analise!$H$2:$H$4546,B14,Base_Analise!$I$2:$I$4546,"Entregue") | D14: =SUMIFS(Base_Analise!$S$2:$S$4546,Base_Analise!$G$2:$G$4546,A14,Base_Analise!$H$2:$H$4546,B14,Base_Analise!$I$2:$I$4546,"Entregue")+SUMIFS(Base_Analise!$T$2:$T$4546,Base_Analise!$G$2:$G$4546,A14,Base_Analise!$H$2:$H$4546,B14,Base_Analise!$I$2:$I$4546,"Entregue") | E14: =SUMIFS(Base_Analise!$U$2:$U$4546,Base_Analise!$G$2:$G$4546,A14,Base_Analise!$H$2:$H$4546,B14,Base_Analise!$I$2:$I$4546,"Entregue") | F14: =SUMIFS(Base_Analise!$W$2:$W$4546,Base_Analise!$G$2:$G$4546,A14,Base_Analise!$H$2:$H$4546,B14,Base_Analise!$I$2:$I$4546,"Entregue") | G14: =IFERROR(F14/C14,0) | H14: =COUNTIFS(Pedidos!$E$2:$E$1801,"Entregue",Pedidos!$B$2:$B$1801,">="&DATE(A14,B14,1),Pedidos!$B$2:$B$1801,"<"&EDATE(DATE(A14,B14,1),1)) | I14: =DATE(A14,B14,1)
A15: 2024 | B15: 11 | C15: =SUMIFS(Base_Analise!$R$2:$R$4546,Base_Analise!$G$2:$G$4546,A15,Base_Analise!$H$2:$H$4546,B15,Base_Analise!$I$2:$I$4546,"Entregue") | D15: =SUMIFS(Base_Analise!$S$2:$S$4546,Base_Analise!$G$2:$G$4546,A15,Base_Analise!$H$2:$H$4546,B15,Base_Analise!$I$2:$I$4546,"Entregue")+SUMIFS(Base_Analise!$T$2:$T$4546,Base_Analise!$G$2:$G$4546,A15,Base_Analise!$H$2:$H$4546,B15,Base_Analise!$I$2:$I$4546,"Entregue") | E15: =SUMIFS(Base_Analise!$U$2:$U$4546,Base_Analise!$G$2:$G$4546,A15,Base_Analise!$H$2:$H$4546,B15,Base_Analise!$I$2:$I$4546,"Entregue") | F15: =SUMIFS(Base_Analise!$W$2:$W$4546,Base_Analise!$G$2:$G$4546,A15,Base_Analise!$H$2:$H$4546,B15,Base_Analise!$I$2:$I$4546,"Entregue") | G15: =IFERROR(F15/C15,0) | H15: =COUNTIFS(Pedidos!$E$2:$E$1801,"Entregue",Pedidos!$B$2:$B$1801,">="&DATE(A15,B15,1),Pedidos!$B$2:$B$1801,"<"&EDATE(DATE(A15,B15,1),1)) | I15: =DATE(A15,B15,1)
A16: 2024 | B16: 12 | C16: =SUMIFS(Base_Analise!$R$2:$R$4546,Base_Analise!$G$2:$G$4546,A16,Base_Analise!$H$2:$H$4546,B16,Base_Analise!$I$2:$I$4546,"Entregue") | D16: =SUMIFS(Base_Analise!$S$2:$S$4546,Base_Analise!$G$2:$G$4546,A16,Base_Analise!$H$2:$H$4546,B16,Base_Analise!$I$2:$I$4546,"Entregue")+SUMIFS(Base_Analise!$T$2:$T$4546,Base_Analise!$G$2:$G$4546,A16,Base_Analise!$H$2:$H$4546,B16,Base_Analise!$I$2:$I$4546,"Entregue") | E16: =SUMIFS(Base_Analise!$U$2:$U$4546,Base_Analise!$G$2:$G$4546,A16,Base_Analise!$H$2:$H$4546,B16,Base_Analise!$I$2:$I$4546,"Entregue") | F16: =SUMIFS(Base_Analise!$W$2:$W$4546,Base_Analise!$G$2:$G$4546,A16,Base_Analise!$H$2:$H$4546,B16,Base_Analise!$I$2:$I$4546,"Entregue") | G16: =IFERROR(F16/C16,0) | H16: =COUNTIFS(Pedidos!$E$2:$E$1801,"Entregue",Pedidos!$B$2:$B$1801,">="&DATE(A16,B16,1),Pedidos!$B$2:$B$1801,"<"&EDATE(DATE(A16,B16,1),1)) | I16: =DATE(A16,B16,1)
... A28: 2025 | B28: 12 | C28: =SUMIFS(Base_Analise!$R$2:$R$4546,Base_Analise!$G$2:$G$4546,A28,Base_Analise!$H$2:$H$4546,B28,Base_Analise!$I$2:$I$4546,"Entregue") | D28: =SUMIFS(Base_Analise!$S$2:$S$4546,Base_Analise!$G$2:$G$4546,A28,Base_Analise!$H$2:$H$4546,B28,Base_Analise!$I$2:$I$4546,"Entregue")+SUMIFS(Base_Analise!$T$2:$T$4546,Base_Analise!$G$2:$G$4546,A28,Base_Analise!$H$2:$H$4546,B28,Base_Analise!$I$2:$I$4546,"Entregue") | E28: =SUMIFS(Base_Analise!$U$2:$U$4546,Base_Analise!$G$2:$G$4546,A28,Base_Analise!$H$2:$H$4546,B28,Base_Analise!$I$2:$I$4546,"Entregue") | F28: =SUMIFS(Base_Analise!$W$2:$W$4546,Base_Analise!$G$2:$G$4546,A28,Base_Analise!$H$2:$H$4546,B28,Base_Analise!$I$2:$I$4546,"Entregue") | G28: =IFERROR(F28/C28,0) | H28: =COUNTIFS(Pedidos!$E$2:$E$1801,"Entregue",Pedidos!$B$2:$B$1801,">="&DATE(A28,B28,1),Pedidos!$B$2:$B$1801,"<"&EDATE(DATE(A28,B28,1),1)) | I28: =DATE(A28,B28,1)

Sheet Lojas_Metas
A1: DESEMPENHO DAS LOJAS
A2: Receita líquida e lucro por loja; metas somadas para todo o período disponível.
A4: LojaID | B4: NomeLoja | C4: Receita Líquida | D4: Lucro Após Descontos | E4: Margem | F4: Metas Acumuladas | G4: Atingimento
A5: L01 | B5: Loja Paulista | C5: =SUMIFS(Base_Analise!$U$2:$U$4546,Base_Analise!$K$2:$K$4546,A5,Base_Analise!$I$2:$I$4546,"Entregue") | D5: =SUMIFS(Base_Analise!$W$2:$W$4546,Base_Analise!$K$2:$K$4546,A5,Base_Analise!$I$2:$I$4546,"Entregue") | E5: =IFERROR(D5/C5,0) | F5: =SUMIFS(MetasMensais!$C$2:$C$193,MetasMensais!$A$2:$A$193,A5) | G5: =IFERROR(C5/F5,0)
A6: L02 | B6: Loja Campinas | C6: =SUMIFS(Base_Analise!$U$2:$U$4546,Base_Analise!$K$2:$K$4546,A6,Base_Analise!$I$2:$I$4546,"Entregue") | D6: =SUMIFS(Base_Analise!$W$2:$W$4546,Base_Analise!$K$2:$K$4546,A6,Base_Analise!$I$2:$I$4546,"Entregue") | E6: =IFERROR(D6/C6,0) | F6: =SUMIFS(MetasMensais!$C$2:$C$193,MetasMensais!$A$2:$A$193,A6) | G6: =IFERROR(C6/F6,0)
A7: L03 | B7: Loja Carioca | C7: =SUMIFS(Base_Analise!$U$2:$U$4546,Base_Analise!$K$2:$K$4546,A7,Base_Analise!$I$2:$I$4546,"Entregue") | D7: =SUMIFS(Base_Analise!$W$2:$W$4546,Base_Analise!$K$2:$K$4546,A7,Base_Analise!$I$2:$I$4546,"Entregue") | E7: =IFERROR(D7/C7,0) | F7: =SUMIFS(MetasMensais!$C$2:$C$193,MetasMensais!$A$2:$A$193,A7) | G7: =IFERROR(C7/F7,0)
A8: L04 | B8: Loja Minas | C8: =SUMIFS(Base_Analise!$U$2:$U$4546,Base_Analise!$K$2:$K$4546,A8,Base_Analise!$I$2:$I$4546,"Entregue") | D8: =SUMIFS(Base_Analise!$W$2:$W$4546,Base_Analise!$K$2:$K$4546,A8,Base_Analise!$I$2:$I$4546,"Entregue") | E8: =IFERROR(D8/C8,0) | F8: =SUMIFS(MetasMensais!$C$2:$C$193,MetasMensais!$A$2:$A$193,A8) | G8: =IFERROR(C8/F8,0)
A9: L05 | B9: Loja Curitiba | C9: =SUMIFS(Base_Analise!$U$2:$U$4546,Base_Analise!$K$2:$K$4546,A9,Base_Analise!$I$2:$I$4546,"Entregue") | D9: =SUMIFS(Base_Analise!$W$2:$W$4546,Base_Analise!$K$2:$K$4546,A9,Base_Analise!$I$2:$I$4546,"Entregue") | E9: =IFERROR(D9/C9,0) | F9: =SUMIFS(MetasMensais!$C$2:$C$193,MetasMensais!$A$2:$A$193,A9) | G9: =IFERROR(C9/F9,0)
A10: L06 | B10: Loja Gaúcha | C10: =SUMIFS(Base_Analise!$U$2:$U$4546,Base_Analise!$K$2:$K$4546,A10,Base_Analise!$I$2:$I$4546,"Entregue") | D10: =SUMIFS(Base_Analise!$W$2:$W$4546,Base_Analise!$K$2:$K$4546,A10,Base_Analise!$I$2:$I$4546,"Entregue") | E10: =IFERROR(D10/C10,0) | F10: =SUMIFS(MetasMensais!$C$2:$C$193,MetasMensais!$A$2:$A$193,A10) | G10: =IFERROR(C10/F10,0)
A11: L07 | B11: Loja Capital | C11: =SUMIFS(Base_Analise!$U$2:$U$4546,Base_Analise!$K$2:$K$4546,A11,Base_Analise!$I$2:$I$4546,"Entregue") | D11: =SUMIFS(Base_Analise!$W$2:$W$4546,Base_Analise!$K$2:$K$4546,A11,Base_Analise!$I$2:$I$4546,"Entregue") | E11: =IFERROR(D11/C11,0) | F11: =SUMIFS(MetasMensais!$C$2:$C$193,MetasMensais!$A$2:$A$193,A11) | G11: =IFERROR(C11/F11,0)
A12: L08 | B12: Loja Recife | C12: =SUMIFS(Base_Analise!$U$2:$U$4546,Base_Analise!$K$2:$K$4546,A12,Base_Analise!$I$2:$I$4546,"Entregue") | D12: =SUMIFS(Base_Analise!$W$2:$W$4546,Base_Analise!$K$2:$K$4546,A12,Base_Analise!$I$2:$I$4546,"Entregue") | E12: =IFERROR(D12/C12,0) | F12: =SUMIFS(MetasMensais!$C$2:$C$193,MetasMensais!$A$2:$A$193,A12) | G12: =IFERROR(C12/F12,0)

Sheet Metas_Mensais
A1: METAS MENSAIS POR LOJA
A2: Compara a receita líquida entregue com a meta da loja em cada mês.
A4: LojaID | B4: Mês Referência | C4: Receita Líquida | D4: Diferença vs Meta | E4: Atingimento | F4: Status da Meta
A5: L01 | B5: 45292 | C5: =SUMIFS(Base_Analise!$U$2:$U$4546,Base_Analise!$K$2:$K$4546,A5,Base_Analise!$F$2:$F$4546,">="&B5,Base_Analise!$F$2:$F$4546,"<"&EDATE(B5,1),Base_Analise!$I$2:$I$4546,"Entregue") | D5: =C5-MetasMensais!C2 | E5: =IFERROR(C5/MetasMensais!C2,0) | F5: =IF(C5>=MetasMensais!C2,"Atingida","Não atingida")
A6: L01 | B6: 45323 | C6: =SUMIFS(Base_Analise!$U$2:$U$4546,Base_Analise!$K$2:$K$4546,A6,Base_Analise!$F$2:$F$4546,">="&B6,Base_Analise!$F$2:$F$4546,"<"&EDATE(B6,1),Base_Analise!$I$2:$I$4546,"Entregue") | D6: =C6-MetasMensais!C3 | E6: =IFERROR(C6/MetasMensais!C3,0) | F6: =IF(C6>=MetasMensais!C3,"Atingida","Não atingida")
A7: L01 | B7: 45352 | C7: =SUMIFS(Base_Analise!$U$2:$U$4546,Base_Analise!$K$2:$K$4546,A7,Base_Analise!$F$2:$F$4546,">="&B7,Base_Analise!$F$2:$F$4546,"<"&EDATE(B7,1),Base_Analise!$I$2:$I$4546,"Entregue") | D7: =C7-MetasMensais!C4 | E7: =IFERROR(C7/MetasMensais!C4,0) | F7: =IF(C7>=MetasMensais!C4,"Atingida","Não atingida")
A8: L01 | B8: 45383 | C8: =SUMIFS(Base_Analise!$U$2:$U$4546,Base_Analise!$K$2:$K$4546,A8,Base_Analise!$F$2:$F$4546,">="&B8,Base_Analise!$F$2:$F$4546,"<"&EDATE(B8,1),Base_Analise!$I$2:$I$4546,"Entregue") | D8: =C8-MetasMensais!C5 | E8: =IFERROR(C8/MetasMensais!C5,0) | F8: =IF(C8>=MetasMensais!C5,"Atingida","Não atingida")
A9: L01 | B9: 45413 | C9: =SUMIFS(Base_Analise!$U$2:$U$4546,Base_Analise!$K$2:$K$4546,A9,Base_Analise!$F$2:$F$4546,">="&B9,Base_Analise!$F$2:$F$4546,"<"&EDATE(B9,1),Base_Analise!$I$2:$I$4546,"Entregue") | D9: =C9-MetasMensais!C6 | E9: =IFERROR(C9/MetasMensais!C6,0) | F9: =IF(C9>=MetasMensais!C6,"Atingida","Não atingida")
A10: L01 | B10: 45444 | C10: =SUMIFS(Base_Analise!$U$2:$U$4546,Base_Analise!$K$2:$K$4546,A10,Base_Analise!$F$2:$F$4546,">="&B10,Base_Analise!$F$2:$F$4546,"<"&EDATE(B10,1),Base_Analise!$I$2:$I$4546,"Entregue") | D10: =C10-MetasMensais!C7 | E10: =IFERROR(C10/MetasMensais!C7,0) | F10: =IF(C10>=MetasMensais!C7,"Atingida","Não atingida")
A11: L01 | B11: 45474 | C11: =SUMIFS(Base_Analise!$U$2:$U$4546,Base_Analise!$K$2:$K$4546,A11,Base_Analise!$F$2:$F$4546,">="&B11,Base_Analise!$F$2:$F$4546,"<"&EDATE(B11,1),Base_Analise!$I$2:$I$4546,"Entregue") | D11: =C11-MetasMensais!C8 | E11: =IFERROR(C11/MetasMensais!C8,0) | F11: =IF(C11>=MetasMensais!C8,"Atingida","Não atingida")
A12: L01 | B12: 45505 | C12: =SUMIFS(Base_Analise!$U$2:$U$4546,Base_Analise!$K$2:$K$4546,A12,Base_Analise!$F$2:$F$4546,">="&B12,Base_Analise!$F$2:$F$4546,"<"&EDATE(B12,1),Base_Analise!$I$2:$I$4546,"Entregue") | D12: =C12-MetasMensais!C9 | E12: =IFERROR(C12/MetasMensais!C9,0) | F12: =IF(C12>=MetasMensais!C9,"Atingida","Não atingida")
A13: L01 | B13: 45536 | C13: =SUMIFS(Base_Analise!$U$2:$U$4546,Base_Analise!$K$2:$K$4546,A13,Base_Analise!$F$2:$F$4546,">="&B13,Base_Analise!$F$2:$F$4546,"<"&EDATE(B13,1),Base_Analise!$I$2:$I$4546,"Entregue") | D13: =C13-MetasMensais!C10 | E13: =IFERROR(C13/MetasMensais!C10,0) | F13: =IF(C13>=MetasMensais!C10,"Atingida","Não atingida")
A14: L01 | B14: 45566 | C14: =SUMIFS(Base_Analise!$U$2:$U$4546,Base_Analise!$K$2:$K$4546,A14,Base_Analise!$F$2:$F$4546,">="&B14,Base_Analise!$F$2:$F$4546,"<"&EDATE(B14,1),Base_Analise!$I$2:$I$4546,"Entregue") | D14: =C14-MetasMensais!C11 | E14: =IFERROR(C14/MetasMensais!C11,0) | F14: =IF(C14>=MetasMensais!C11,"Atingida","Não atingida")
A15: L01 | B15: 45597 | C15: =SUMIFS(Base_Analise!$U$2:$U$4546,Base_Analise!$K$2:$K$4546,A15,Base_Analise!$F$2:$F$4546,">="&B15,Base_Analise!$F$2:$F$4546,"<"&EDATE(B15,1),Base_Analise!$I$2:$I$4546,"Entregue") | D15: =C15-MetasMensais!C12 | E15: =IFERROR(C15/MetasMensais!C12,0) | F15: =IF(C15>=MetasMensais!C12,"Atingida","Não atingida")
A16: L01 | B16: 45627 | C16: =SUMIFS(Base_Analise!$U$2:$U$4546,Base_Analise!$K$2:$K$4546,A16,Base_Analise!$F$2:$F$4546,">="&B16,Base_Analise!$F$2:$F$4546,"<"&EDATE(B16,1),Base_Analise!$I$2:$I$4546,"Entregue") | D16: =C16-MetasMensais!C13 | E16: =IFERROR(C16/MetasMensais!C13,0) | F16: =IF(C16>=MetasMensais!C13,"Atingida","Não atingida")
... A196: L08 | B196: 45992 | C196: =SUMIFS(Base_Analise!$U$2:$U$4546,Base_Analise!$K$2:$K$4546,A196,Base_Analise!$F$2:$F$4546,">="&B196,Base_Analise!$F$2:$F$4546,"<"&EDATE(B196,1),Base_Analise!$I$2:$I$4546,"Entregue") | D196: =C196-MetasMensais!C193 | E196: =IFERROR(C196/MetasMensais!C193,0) | F196: =IF(C196>=MetasMensais!C193,"Atingida","Não atingida")

Sheet Categorias_Produtos
A1: CATEGORIAS E PRODUTOS
A2: Receita, receita líquida, lucro e margem por categoria e produto.
A4: Categoria | B4: Faturamento Bruto | C4: Receita Líquida | D4: Lucro Após Descontos
A5: Eletroportáteis | B5: =SUMIFS(Base_Analise!$R$2:$R$4546,Base_Analise!$O$2:$O$4546,A5,Base_Analise!$I$2:$I$4546,"Entregue") | C5: =SUMIFS(Base_Analise!$U$2:$U$4546,Base_Analise!$O$2:$O$4546,A5,Base_Analise!$I$2:$I$4546,"Entregue") | D5: =SUMIFS(Base_Analise!$W$2:$W$4546,Base_Analise!$O$2:$O$4546,A5,Base_Analise!$I$2:$I$4546,"Entregue")
A6: Informática | B6: =SUMIFS(Base_Analise!$R$2:$R$4546,Base_Analise!$O$2:$O$4546,A6,Base_Analise!$I$2:$I$4546,"Entregue") | C6: =SUMIFS(Base_Analise!$U$2:$U$4546,Base_Analise!$O$2:$O$4546,A6,Base_Analise!$I$2:$I$4546,"Entregue") | D6: =SUMIFS(Base_Analise!$W$2:$W$4546,Base_Analise!$O$2:$O$4546,A6,Base_Analise!$I$2:$I$4546,"Entregue")
A7: Móveis | B7: =SUMIFS(Base_Analise!$R$2:$R$4546,Base_Analise!$O$2:$O$4546,A7,Base_Analise!$I$2:$I$4546,"Entregue") | C7: =SUMIFS(Base_Analise!$U$2:$U$4546,Base_Analise!$O$2:$O$4546,A7,Base_Analise!$I$2:$I$4546,"Entregue") | D7: =SUMIFS(Base_Analise!$W$2:$W$4546,Base_Analise!$O$2:$O$4546,A7,Base_Analise!$I$2:$I$4546,"Entregue")
A8: Papelaria | B8: =SUMIFS(Base_Analise!$R$2:$R$4546,Base_Analise!$O$2:$O$4546,A8,Base_Analise!$I$2:$I$4546,"Entregue") | C8: =SUMIFS(Base_Analise!$U$2:$U$4546,Base_Analise!$O$2:$O$4546,A8,Base_Analise!$I$2:$I$4546,"Entregue") | D8: =SUMIFS(Base_Analise!$W$2:$W$4546,Base_Analise!$O$2:$O$4546,A8,Base_Analise!$I$2:$I$4546,"Entregue")
A9: Telefonia | B9: =SUMIFS(Base_Analise!$R$2:$R$4546,Base_Analise!$O$2:$O$4546,A9,Base_Analise!$I$2:$I$4546,"Entregue") | C9: =SUMIFS(Base_Analise!$U$2:$U$4546,Base_Analise!$O$2:$O$4546,A9,Base_Analise!$I$2:$I$4546,"Entregue") | D9: =SUMIFS(Base_Analise!$W$2:$W$4546,Base_Analise!$O$2:$O$4546,A9,Base_Analise!$I$2:$I$4546,"Entregue")
A12: Produto | B12: Categoria | C12: Faturamento Bruto | D12: Receita Líquida | E12: Lucro Após Descontos | F12: Margem
A13: =Produtos!B2 | B13: =Produtos!C2 | C13: =SUMIFS(Base_Analise!$R$2:$R$4546,Base_Analise!$N$2:$N$4546,A13,Base_Analise!$I$2:$I$4546,"Entregue") | D13: =SUMIFS(Base_Analise!$U$2:$U$4546,Base_Analise!$N$2:$N$4546,A13,Base_Analise!$I$2:$I$4546,"Entregue") | E13: =SUMIFS(Base_Analise!$W$2:$W$4546,Base_Analise!$N$2:$N$4546,A13,Base_Analise!$I$2:$I$4546,"Entregue") | F13: =IFERROR(E13/D13,0)
A14: =Produtos!B3 | B14: =Produtos!C3 | C14: =SUMIFS(Base_Analise!$R$2:$R$4546,Base_Analise!$N$2:$N$4546,A14,Base_Analise!$I$2:$I$4546,"Entregue") | D14: =SUMIFS(Base_Analise!$U$2:$U$4546,Base_Analise!$N$2:$N$4546,A14,Base_Analise!$I$2:$I$4546,"Entregue") | E14: =SUMIFS(Base_Analise!$W$2:$W$4546,Base_Analise!$N$2:$N$4546,A14,Base_Analise!$I$2:$I$4546,"Entregue") | F14: =IFERROR(E14/D14,0)
A15: =Produtos!B4 | B15: =Produtos!C4 | C15: =SUMIFS(Base_Analise!$R$2:$R$4546,Base_Analise!$N$2:$N$4546,A15,Base_Analise!$I$2:$I$4546,"Entregue") | D15: =SUMIFS(Base_Analise!$U$2:$U$4546,Base_Analise!$N$2:$N$4546,A15,Base_Analise!$I$2:$I$4546,"Entregue") | E15: =SUMIFS(Base_Analise!$W$2:$W$4546,Base_Analise!$N$2:$N$4546,A15,Base_Analise!$I$2:$I$4546,"Entregue") | F15: =IFERROR(E15/D15,0)
A16: =Produtos!B5 | B16: =Produtos!C5 | C16: =SUMIFS(Base_Analise!$R$2:$R$4546,Base_Analise!$N$2:$N$4546,A16,Base_Analise!$I$2:$I$4546,"Entregue") | D16: =SUMIFS(Base_Analise!$U$2:$U$4546,Base_Analise!$N$2:$N$4546,A16,Base_Analise!$I$2:$I$4546,"Entregue") | E16: =SUMIFS(Base_Analise!$W$2:$W$4546,Base_Analise!$N$2:$N$4546,A16,Base_Analise!$I$2:$I$4546,"Entregue") | F16: =IFERROR(E16/D16,0)
A17: =Produtos!B6 | B17: =Produtos!C6 | C17: =SUMIFS(Base_Analise!$R$2:$R$4546,Base_Analise!$N$2:$N$4546,A17,Base_Analise!$I$2:$I$4546,"Entregue") | D17: =SUMIFS(Base_Analise!$U$2:$U$4546,Base_Analise!$N$2:$N$4546,A17,Base_Analise!$I$2:$I$4546,"Entregue") | E17: =SUMIFS(Base_Analise!$W$2:$W$4546,Base_Analise!$N$2:$N$4546,A17,Base_Analise!$I$2:$I$4546,"Entregue") | F17: =IFERROR(E17/D17,0)
A18: =Produtos!B7 | B18: =Produtos!C7 | C18: =SUMIFS(Base_Analise!$R$2:$R$4546,Base_Analise!$N$2:$N$4546,A18,Base_Analise!$I$2:$I$4546,"Entregue") | D18: =SUMIFS(Base_Analise!$U$2:$U$4546,Base_Analise!$N$2:$N$4546,A18,Base_Analise!$I$2:$I$4546,"Entregue") | E18: =SUMIFS(Base_Analise!$W$2:$W$4546,Base_Analise!$N$2:$N$4546,A18,Base_Analise!$I$2:$I$4546,"Entregue") | F18: =IFERROR(E18/D18,0)
A19: =Produtos!B8 | B19: =Produtos!C8 | C19: =SUMIFS(Base_Analise!$R$2:$R$4546,Base_Analise!$N$2:$N$4546,A19,Base_Analise!$I$2:$I$4546,"Entregue") | D19: =SUMIFS(Base_Analise!$U$2:$U$4546,Base_Analise!$N$2:$N$4546,A19,Base_Analise!$I$2:$I$4546,"Entregue") | E19: =SUMIFS(Base_Analise!$W$2:$W$4546,Base_Analise!$N$2:$N$4546,A19,Base_Analise!$I$2:$I$4546,"Entregue") | F19: =IFERROR(E19/D19,0)
A20: =Produtos!B9 | B20: =Produtos!C9 | C20: =SUMIFS(Base_Analise!$R$2:$R$4546,Base_Analise!$N$2:$N$4546,A20,Base_Analise!$I$2:$I$4546,"Entregue") | D20: =SUMIFS(Base_Analise!$U$2:$U$4546,Base_Analise!$N$2:$N$4546,A20,Base_Analise!$I$2:$I$4546,"Entregue") | E20: =SUMIFS(Base_Analise!$W$2:$W$4546,Base_Analise!$N$2:$N$4546,A20,Base_Analise!$I$2:$I$4546,"Entregue") | F20: =IFERROR(E20/D20,0)
A21: =Produtos!B10 | B21: =Produtos!C10 | C21: =SUMIFS(Base_Analise!$R$2:$R$4546,Base_Analise!$N$2:$N$4546,A21,Base_Analise!$I$2:$I$4546,"Entregue") | D21: =SUMIFS(Base_Analise!$U$2:$U$4546,Base_Analise!$N$2:$N$4546,A21,Base_Analise!$I$2:$I$4546,"Entregue") | E21: =SUMIFS(Base_Analise!$W$2:$W$4546,Base_Analise!$N$2:$N$4546,A21,Base_Analise!$I$2:$I$4546,"Entregue") | F21: =IFERROR(E21/D21,0)
A22: =Produtos!B11 | B22: =Produtos!C11 | C22: =SUMIFS(Base_Analise!$R$2:$R$4546,Base_Analise!$N$2:$N$4546,A22,Base_Analise!$I$2:$I$4546,"Entregue") | D22: =SUMIFS(Base_Analise!$U$2:$U$4546,Base_Analise!$N$2:$N$4546,A22,Base_Analise!$I$2:$I$4546,"Entregue") | E22: =SUMIFS(Base_Analise!$W$2:$W$4546,Base_Analise!$N$2:$N$4546,A22,Base_Analise!$I$2:$I$4546,"Entregue") | F22: =IFERROR(E22/D22,0)
A23: =Produtos!B12 | B23: =Produtos!C12 | C23: =SUMIFS(Base_Analise!$R$2:$R$4546,Base_Analise!$N$2:$N$4546,A23,Base_Analise!$I$2:$I$4546,"Entregue") | D23: =SUMIFS(Base_Analise!$U$2:$U$4546,Base_Analise!$N$2:$N$4546,A23,Base_Analise!$I$2:$I$4546,"Entregue") | E23: =SUMIFS(Base_Analise!$W$2:$W$4546,Base_Analise!$N$2:$N$4546,A23,Base_Analise!$I$2:$I$4546,"Entregue") | F23: =IFERROR(E23/D23,0)
A24: =Produtos!B13 | B24: =Produtos!C13 | C24: =SUMIFS(Base_Analise!$R$2:$R$4546,Base_Analise!$N$2:$N$4546,A24,Base_Analise!$I$2:$I$4546,"Entregue") | D24: =SUMIFS(Base_Analise!$U$2:$U$4546,Base_Analise!$N$2:$N$4546,A24,Base_Analise!$I$2:$I$4546,"Entregue") | E24: =SUMIFS(Base_Analise!$W$2:$W$4546,Base_Analise!$N$2:$N$4546,A24,Base_Analise!$I$2:$I$4546,"Entregue") | F24: =IFERROR(E24/D24,0)
... A82: =Produtos!B71 | B82: =Produtos!C71 | C82: =SUMIFS(Base_Analise!$R$2:$R$4546,Base_Analise!$N$2:$N$4546,A82,Base_Analise!$I$2:$I$4546,"Entregue") | D82: =SUMIFS(Base_Analise!$U$2:$U$4546,Base_Analise!$N$2:$N$4546,A82,Base_Analise!$I$2:$I$4546,"Entregue") | E82: =SUMIFS(Base_Analise!$W$2:$W$4546,Base_Analise!$N$2:$N$4546,A82,Base_Analise!$I$2:$I$4546,"Entregue") | F82: =IFERROR(E82/D82,0)

Sheet Clientes_Receita
A1: CLIENTES E SEGMENTOS
A2: Receita líquida e lucro por cliente; use filtros para analisar segmentos.
A4: ClienteID | B4: NomeCliente | C4: Segmento | D4: Receita Líquida | E4: Lucro Após Descontos
A5: =Clientes!A2 | B5: =Clientes!B2 | C5: =Clientes!C2 | D5: =SUMIFS(Base_Analise!$U$2:$U$4546,Base_Analise!$J$2:$J$4546,A5,Base_Analise!$I$2:$I$4546,"Entregue") | E5: =SUMIFS(Base_Analise!$W$2:$W$4546,Base_Analise!$J$2:$J$4546,A5,Base_Analise!$I$2:$I$4546,"Entregue")
A6: =Clientes!A3 | B6: =Clientes!B3 | C6: =Clientes!C3 | D6: =SUMIFS(Base_Analise!$U$2:$U$4546,Base_Analise!$J$2:$J$4546,A6,Base_Analise!$I$2:$I$4546,"Entregue") | E6: =SUMIFS(Base_Analise!$W$2:$W$4546,Base_Analise!$J$2:$J$4546,A6,Base_Analise!$I$2:$I$4546,"Entregue")
A7: =Clientes!A4 | B7: =Clientes!B4 | C7: =Clientes!C4 | D7: =SUMIFS(Base_Analise!$U$2:$U$4546,Base_Analise!$J$2:$J$4546,A7,Base_Analise!$I$2:$I$4546,"Entregue") | E7: =SUMIFS(Base_Analise!$W$2:$W$4546,Base_Analise!$J$2:$J$4546,A7,Base_Analise!$I$2:$I$4546,"Entregue")
A8: =Clientes!A5 | B8: =Clientes!B5 | C8: =Clientes!C5 | D8: =SUMIFS(Base_Analise!$U$2:$U$4546,Base_Analise!$J$2:$J$4546,A8,Base_Analise!$I$2:$I$4546,"Entregue") | E8: =SUMIFS(Base_Analise!$W$2:$W$4546,Base_Analise!$J$2:$J$4546,A8,Base_Analise!$I$2:$I$4546,"Entregue")
A9: =Clientes!A6 | B9: =Clientes!B6 | C9: =Clientes!C6 | D9: =SUMIFS(Base_Analise!$U$2:$U$4546,Base_Analise!$J$2:$J$4546,A9,Base_Analise!$I$2:$I$4546,"Entregue") | E9: =SUMIFS(Base_Analise!$W$2:$W$4546,Base_Analise!$J$2:$J$4546,A9,Base_Analise!$I$2:$I$4546,"Entregue")
A10: =Clientes!A7 | B10: =Clientes!B7 | C10: =Clientes!C7 | D10: =SUMIFS(Base_Analise!$U$2:$U$4546,Base_Analise!$J$2:$J$4546,A10,Base_Analise!$I$2:$I$4546,"Entregue") | E10: =SUMIFS(Base_Analise!$W$2:$W$4546,Base_Analise!$J$2:$J$4546,A10,Base_Analise!$I$2:$I$4546,"Entregue")
A11: =Clientes!A8 | B11: =Clientes!B8 | C11: =Clientes!C8 | D11: =SUMIFS(Base_Analise!$U$2:$U$4546,Base_Analise!$J$2:$J$4546,A11,Base_Analise!$I$2:$I$4546,"Entregue") | E11: =SUMIFS(Base_Analise!$W$2:$W$4546,Base_Analise!$J$2:$J$4546,A11,Base_Analise!$I$2:$I$4546,"Entregue")
A12: =Clientes!A9 | B12: =Clientes!B9 | C12: =Clientes!C9 | D12: =SUMIFS(Base_Analise!$U$2:$U$4546,Base_Analise!$J$2:$J$4546,A12,Base_Analise!$I$2:$I$4546,"Entregue") | E12: =SUMIFS(Base_Analise!$W$2:$W$4546,Base_Analise!$J$2:$J$4546,A12,Base_Analise!$I$2:$I$4546,"Entregue")
A13: =Clientes!A10 | B13: =Clientes!B10 | C13: =Clientes!C10 | D13: =SUMIFS(Base_Analise!$U$2:$U$4546,Base_Analise!$J$2:$J$4546,A13,Base_Analise!$I$2:$I$4546,"Entregue") | E13: =SUMIFS(Base_Analise!$W$2:$W$4546,Base_Analise!$J$2:$J$4546,A13,Base_Analise!$I$2:$I$4546,"Entregue")
A14: =Clientes!A11 | B14: =Clientes!B11 | C14: =Clientes!C11 | D14: =SUMIFS(Base_Analise!$U$2:$U$4546,Base_Analise!$J$2:$J$4546,A14,Base_Analise!$I$2:$I$4546,"Entregue") | E14: =SUMIFS(Base_Analise!$W$2:$W$4546,Base_Analise!$J$2:$J$4546,A14,Base_Analise!$I$2:$I$4546,"Entregue")
A15: =Clientes!A12 | B15: =Clientes!B12 | C15: =Clientes!C12 | D15: =SUMIFS(Base_Analise!$U$2:$U$4546,Base_Analise!$J$2:$J$4546,A15,Base_Analise!$I$2:$I$4546,"Entregue") | E15: =SUMIFS(Base_Analise!$W$2:$W$4546,Base_Analise!$J$2:$J$4546,A15,Base_Analise!$I$2:$I$4546,"Entregue")
A16: =Clientes!A13 | B16: =Clientes!B13 | C16: =Clientes!C13 | D16: =SUMIFS(Base_Analise!$U$2:$U$4546,Base_Analise!$J$2:$J$4546,A16,Base_Analise!$I$2:$I$4546,"Entregue") | E16: =SUMIFS(Base_Analise!$W$2:$W$4546,Base_Analise!$J$2:$J$4546,A16,Base_Analise!$I$2:$I$4546,"Entregue")
... A354: =Clientes!A351 | B354: =Clientes!B351 | C354: =Clientes!C351 | D354: =SUMIFS(Base_Analise!$U$2:$U$4546,Base_Analise!$J$2:$J$4546,A354,Base_Analise!$I$2:$I$4546,"Entregue") | E354: =SUMIFS(Base_Analise!$W$2:$W$4546,Base_Analise!$J$2:$J$4546,A354,Base_Analise!$I$2:$I$4546,"Entregue")

Sheet Pagamentos_Descontos
A1: PAGAMENTOS E DESCONTOS
A2: Formas de pagamento e descontos por mês. Pedidos entregues são destacados separadamente.
A4: Forma de Pagamento | B4: Todos os Pedidos | C4: Pedidos Entregues | D4: Receita Líquida Entregue
A5: Boleto | B5: =COUNTIF(Pedidos!$F$2:$F$1801,A5) | C5: =COUNTIFS(Pedidos!$F$2:$F$1801,A5,Pedidos!$E$2:$E$1801,"Entregue") | D5: =SUMIFS(Base_Analise!$U$2:$U$4546,Base_Analise!$L$2:$L$4546,A5,Base_Analise!$I$2:$I$4546,"Entregue")
A6: Cartão de crédito | B6: =COUNTIF(Pedidos!$F$2:$F$1801,A6) | C6: =COUNTIFS(Pedidos!$F$2:$F$1801,A6,Pedidos!$E$2:$E$1801,"Entregue") | D6: =SUMIFS(Base_Analise!$U$2:$U$4546,Base_Analise!$L$2:$L$4546,A6,Base_Analise!$I$2:$I$4546,"Entregue")
A7: Cartão de débito | B7: =COUNTIF(Pedidos!$F$2:$F$1801,A7) | C7: =COUNTIFS(Pedidos!$F$2:$F$1801,A7,Pedidos!$E$2:$E$1801,"Entregue") | D7: =SUMIFS(Base_Analise!$U$2:$U$4546,Base_Analise!$L$2:$L$4546,A7,Base_Analise!$I$2:$I$4546,"Entregue")
A8: Pix | B8: =COUNTIF(Pedidos!$F$2:$F$1801,A8) | C8: =COUNTIFS(Pedidos!$F$2:$F$1801,A8,Pedidos!$E$2:$E$1801,"Entregue") | D8: =SUMIFS(Base_Analise!$U$2:$U$4546,Base_Analise!$L$2:$L$4546,A8,Base_Analise!$I$2:$I$4546,"Entregue")
A9: Transferência | B9: =COUNTIF(Pedidos!$F$2:$F$1801,A9) | C9: =COUNTIFS(Pedidos!$F$2:$F$1801,A9,Pedidos!$E$2:$E$1801,"Entregue") | D9: =SUMIFS(Base_Analise!$U$2:$U$4546,Base_Analise!$L$2:$L$4546,A9,Base_Analise!$I$2:$I$4546,"Entregue")
A12: Mês/Ano | B12: Desconto em Itens | C12: Desconto em Pedidos | D12: Descontos Totais | E12: Faturamento Bruto | F12: Receita Líquida
A13: =Resumo_Mensal!I5 | B13: =SUMIFS(Base_Analise!$S$2:$S$4546,Base_Analise!$G$2:$G$4546,Resumo_Mensal!A5,Base_Analise!$H$2:$H$4546,Resumo_Mensal!B5,Base_Analise!$I$2:$I$4546,"Entregue") | C13: =SUMIFS(Base_Analise!$T$2:$T$4546,Base_Analise!$G$2:$G$4546,Resumo_Mensal!A5,Base_Analise!$H$2:$H$4546,Resumo_Mensal!B5,Base_Analise!$I$2:$I$4546,"Entregue") | D13: =B13+C13 | E13: =Resumo_Mensal!C5 | F13: =Resumo_Mensal!E5
A14: =Resumo_Mensal!I6 | B14: =SUMIFS(Base_Analise!$S$2:$S$4546,Base_Analise!$G$2:$G$4546,Resumo_Mensal!A6,Base_Analise!$H$2:$H$4546,Resumo_Mensal!B6,Base_Analise!$I$2:$I$4546,"Entregue") | C14: =SUMIFS(Base_Analise!$T$2:$T$4546,Base_Analise!$G$2:$G$4546,Resumo_Mensal!A6,Base_Analise!$H$2:$H$4546,Resumo_Mensal!B6,Base_Analise!$I$2:$I$4546,"Entregue") | D14: =B14+C14 | E14: =Resumo_Mensal!C6 | F14: =Resumo_Mensal!E6
A15: =Resumo_Mensal!I7 | B15: =SUMIFS(Base_Analise!$S$2:$S$4546,Base_Analise!$G$2:$G$4546,Resumo_Mensal!A7,Base_Analise!$H$2:$H$4546,Resumo_Mensal!B7,Base_Analise!$I$2:$I$4546,"Entregue") | C15: =SUMIFS(Base_Analise!$T$2:$T$4546,Base_Analise!$G$2:$G$4546,Resumo_Mensal!A7,Base_Analise!$H$2:$H$4546,Resumo_Mensal!B7,Base_Analise!$I$2:$I$4546,"Entregue") | D15: =B15+C15 | E15: =Resumo_Mensal!C7 | F15: =Resumo_Mensal!E7
A16: =Resumo_Mensal!I8 | B16: =SUMIFS(Base_Analise!$S$2:$S$4546,Base_Analise!$G$2:$G$4546,Resumo_Mensal!A8,Base_Analise!$H$2:$H$4546,Resumo_Mensal!B8,Base_Analise!$I$2:$I$4546,"Entregue") | C16: =SUMIFS(Base_Analise!$T$2:$T$4546,Base_Analise!$G$2:$G$4546,Resumo_Mensal!A8,Base_Analise!$H$2:$H$4546,Resumo_Mensal!B8,Base_Analise!$I$2:$I$4546,"Entregue") | D16: =B16+C16 | E16: =Resumo_Mensal!C8 | F16: =Resumo_Mensal!E8
A17: =Resumo_Mensal!I9 | B17: =SUMIFS(Base_Analise!$S$2:$S$4546,Base_Analise!$G$2:$G$4546,Resumo_Mensal!A9,Base_Analise!$H$2:$H$4546,Resumo_Mensal!B9,Base_Analise!$I$2:$I$4546,"Entregue") | C17: =SUMIFS(Base_Analise!$T$2:$T$4546,Base_Analise!$G$2:$G$4546,Resumo_Mensal!A9,Base_Analise!$H$2:$H$4546,Resumo_Mensal!B9,Base_Analise!$I$2:$I$4546,"Entregue") | D17: =B17+C17 | E17: =Resumo_Mensal!C9 | F17: =Resumo_Mensal!E9
A18: =Resumo_Mensal!I10 | B18: =SUMIFS(Base_Analise!$S$2:$S$4546,Base_Analise!$G$2:$G$4546,Resumo_Mensal!A10,Base_Analise!$H$2:$H$4546,Resumo_Mensal!B10,Base_Analise!$I$2:$I$4546,"Entregue") | C18: =SUMIFS(Base_Analise!$T$2:$T$4546,Base_Analise!$G$2:$G$4546,Resumo_Mensal!A10,Base_Analise!$H$2:$H$4546,Resumo_Mensal!B10,Base_Analise!$I$2:$I$4546,"Entregue") | D18: =B18+C18 | E18: =Resumo_Mensal!C10 | F18: =Resumo_Mensal!E10
A19: =Resumo_Mensal!I11 | B19: =SUMIFS(Base_Analise!$S$2:$S$4546,Base_Analise!$G$2:$G$4546,Resumo_Mensal!A11,Base_Analise!$H$2:$H$4546,Resumo_Mensal!B11,Base_Analise!$I$2:$I$4546,"Entregue") | C19: =SUMIFS(Base_Analise!$T$2:$T$4546,Base_Analise!$G$2:$G$4546,Resumo_Mensal!A11,Base_Analise!$H$2:$H$4546,Resumo_Mensal!B11,Base_Analise!$I$2:$I$4546,"Entregue") | D19: =B19+C19 | E19: =Resumo_Mensal!C11 | F19: =Resumo_Mensal!E11
A20: =Resumo_Mensal!I12 | B20: =SUMIFS(Base_Analise!$S$2:$S$4546,Base_Analise!$G$2:$G$4546,Resumo_Mensal!A12,Base_Analise!$H$2:$H$4546,Resumo_Mensal!B12,Base_Analise!$I$2:$I$4546,"Entregue") | C20: =SUMIFS(Base_Analise!$T$2:$T$4546,Base_Analise!$G$2:$G$4546,Resumo_Mensal!A12,Base_Analise!$H$2:$H$4546,Resumo_Mensal!B12,Base_Analise!$I$2:$I$4546,"Entregue") | D20: =B20+C20 | E20: =Resumo_Mensal!C12 | F20: =Resumo_Mensal!E12
A21: =Resumo_Mensal!I13 | B21: =SUMIFS(Base_Analise!$S$2:$S$4546,Base_Analise!$G$2:$G$4546,Resumo_Mensal!A13,Base_Analise!$H$2:$H$4546,Resumo_Mensal!B13,Base_Analise!$I$2:$I$4546,"Entregue") | C21: =SUMIFS(Base_Analise!$T$2:$T$4546,Base_Analise!$G$2:$G$4546,Resumo_Mensal!A13,Base_Analise!$H$2:$H$4546,Resumo_Mensal!B13,Base_Analise!$I$2:$I$4546,"Entregue") | D21: =B21+C21 | E21: =Resumo_Mensal!C13 | F21: =Resumo_Mensal!E13
A22: =Resumo_Mensal!I14 | B22: =SUMIFS(Base_Analise!$S$2:$S$4546,Base_Analise!$G$2:$G$4546,Resumo_Mensal!A14,Base_Analise!$H$2:$H$4546,Resumo_Mensal!B14,Base_Analise!$I$2:$I$4546,"Entregue") | C22: =SUMIFS(Base_Analise!$T$2:$T$4546,Base_Analise!$G$2:$G$4546,Resumo_Mensal!A14,Base_Analise!$H$2:$H$4546,Resumo_Mensal!B14,Base_Analise!$I$2:$I$4546,"Entregue") | D22: =B22+C22 | E22: =Resumo_Mensal!C14 | F22: =Resumo_Mensal!E14
